Workbook

Sheet คิดต้นทุน สรุป
B2: ชื่อแบบฟอร์ม : สูตร | V2: เลขที่แบบฟอร์ม : F-OP-RD-002 | AK2: แก้ไขครั้งที่ : 0
B3: เตรียมโดย : - | V3: อนุมัติโดย : -
B5: สูตรผลิตจริง
B6: นามผู้ซื้อ | Z6: เลขที่สูตร
B8: ประเภทของผลิตภัณฑ์ | Z8: วันที่
B10: ชื่อผลิตภัณฑ์ / เลข อย. | Z10: พนักงานขาย
B12: จำนวนที่สั่งผลิต | P12: หน่วย | T12: แคปซูล
AS13: จะส่งให้แพลนนิ่งผลิต
B14: ลำดับ | D14: สารสกัด | P14: ปริมาณ | V14: ปริมาณที่ใช้ | Z14: ร้อยละ | AA14: ราคา / ก.ก. | AE14: ราคา / มก. | AI14: ผู้จัดจำหน่าย | AM14: รหัส | AN14: ราคา/แพ็ค | AO14: ปริมาณ | AP14: ปริมาณ g. | AQ14: ราคา / mg. | AS14: เป็นไฟล์สำหรับคำนวณต้นทุนสาร
B15: No. | P15: (มล.) | V15: ผลิต (ก.ก.) | Z15: (%) (Mg.) | AA15: Price / Kg. | AE15: Price / Mg. | AI15: Supplier | AM15: วัตถุดิบ | AO15: mg.
B16: 1 | V16: =SUM(P16*I12/1000000) -> 0 | Z16: =P16*100/P28 -> #DIV/0! | AE16: =SUM(AA16/1000000*P16) -> 0 | AO16: =+P16*AP31 -> 0 | AP16: =+AO16/1000 -> 0 | AQ16: =SUM(AA16/1000000*AO16) -> 0
B17: 2 | V17: =SUM(P17*I12/1000000) -> 0 | Z17: =P17*100/P28 -> #DIV/0! | AE17: =SUM(AA17/1000000*P17) -> 0 | AO17: =+P17*AP31 -> 0 | AP17: =+AO17/1000 -> 0 | AQ17: =SUM(AA17/1000000*AO17) -> 0
B18: 3 | V18: =SUM(P18*I12/1000000) -> 0 | Z18: =P18*100/P28 -> #DIV/0! | AE18: =SUM(AA18/1000000*P18) -> 0 | AO18: =+P18*AP31 -> 0 | AP18: =+AO18/1000 -> 0 | AQ18: =SUM(AA18/1000000*AO18) -> 0
B19: 4 | V19: =SUM(P19*$I$12/1000000) -> 0 | Z19: =P19*100/$P$28 -> #DIV/0! | AE19: =SUM(AA19/1000000*P19) -> 0 | AO19: =+P19*AP31 -> 0 | AP19: =+AO19/1000 -> 0 | AQ19: =SUM(AA19/1000000*AO19) -> 0
B20: 5 | V20: =SUM(P20*I12/1000000) -> 0 | Z20: =P20*100/P28 -> #DIV/0! | AE20: =SUM(AA20/1000000*P20) -> 0 | AO20: =+P20*AP31 -> 0 | AP20: =+AO20/1000 -> 0 | AQ20: =SUM(AA20/1000000*AO20) -> 0
B21: 6 | V21: =SUM(P21*I12/1000000) -> 0 | Z21: =P21*100/P28 -> #DIV/0! | AE21: =SUM(AA21/1000000*P21) -> 0 | AO21: =+P21*AP31 -> 0 | AP21: =+AO21/1000 -> 0 | AQ21: =SUM(AA21/1000000*AO21) -> 0
B22: 7 | V22: =SUM(P22*I12/1000000) -> 0 | Z22: =P22*100/P28 -> #DIV/0! | AE22: =SUM(AA22/1000000*P22) -> 0 | AO22: =+P22*AP31 -> 0 | AP22: =+AO22/1000 -> 0 | AQ22: =SUM(AA22/1000000*AO22) -> 0
B23: 8 | V23: =SUM(P23*I12/1000000) -> 0 | Z23: =P23*100/P28 -> #DIV/0! | AE23: =SUM(AA23/1000000*P23) -> 0 | AO23: =+P23*AP31 -> 0 | AP23: =+AO23/1000 -> 0 | AQ23: =SUM(AA23/1000000*AO23) -> 0
B24: 9 | V24: =SUM(P24*I12/1000000) -> 0 | Z24: =P24*100/P28 -> #DIV/0! | AE24: =SUM(AA24/1000000*P24) -> 0 | AO24: =+P24*AP31 -> 0 | AP24: =+AO24/1000 -> 0 | AQ24: =SUM(AA24/1000000*AO24) -> 0
B25: 10 | V25: =SUM(P25*I12/1000000) -> 0 | Z25: =P25*100/P28 -> #DIV/0! | AE25: =SUM(AA25/1000000*P25) -> 0 | AO25: =+P25*AP31 -> 0 | AP25: =+AO25/1000 -> 0 | AQ25: =SUM(AA25/1000000*AO25) -> 0
B26: 11 | V26: =SUM(P26*I12/1000000) -> 0 | Z26: =P26*100/P28 -> #DIV/0! | AE26: =SUM(AA26/1000000*P26) -> 0 | AO26: =+P26*AP31 -> 0 | AP26: =+AO26/1000 -> 0 | AQ26: =SUM(AA26/1000000*AO26) -> 0
B27: 12 | V27: =SUM(P27*I12/1000000) -> 0 | Z27: =P27*100/P28 -> #DIV/0! | AE27: =SUM(AA27/1000000*P27) -> 0 | AO27: =+P27*AP31 -> 0 | AP27: =+AO27/1000 -> 0 | AQ27: =SUM(AA27/1000000*AO27) -> 0
B28: ปริมาณส่วนผสม / หน่วย / กก. | P28: =SUM(P16:U27) -> 0 | V28: =SUM(V16:Y27) -> 0 | Z28: =SUM(Z16:Z27) -> #DIV/0! | AE28: ต้นทุนราคา/แพ็ค | AN28: =SUM(AN20:AN27) -> 0 | AO28: =+AE31*AP31 -> 0
B29: งานแคปซูล ( แคปซูลสี ค่าแคปซูล #00 ราคา 0.6 บาท, ค่าแคปซูล #0 ราคา 0.5 บาท ) ( แคปซูลขาว ค่าแคปซูล #00 ราคา 0.2 บาท, ค่าแคปซูล #0 ราคา 0.1 บาท )
B30: ( งานชงดื่ม,กรอกปาก Aluminium Foil ราคา 1.5 บาท ) ( ตอกเม็ด+เคลือบ 0.8 บาท )
B31: แคปซูล #00 DRCap | AA31: ราคา | AE31: 0 | AN31: จำนวน Tester | AP31: =30/0.981 -> 30.58104 | AQ31: =+T12 -> แคปซูล
B33: ราคาต้นทุนส่วนผสม / หน่วย | K33: =SUM(AE16:AH31) -> 0 | O33: =K33-AE31 -> 0 | AI33: รวมราคาต้นทุนส่วนผสม | AO33: =SUM(I12*K33) -> 0
B34: ราคาขาย / หน่วย | O34: =K34-AE31 -> 0 | AI34: รวมราคาขาย | AO34: =SUM(I12*K34) -> 0
B35: กำไร / หน่วย | K35: =SUM(K34-K33) -> 0 | O35: =O34-O33 -> 0 | Z35: =O35*100/O34 -> #DIV/0! | AI35: รวมกำไร | AO35: =SUM(AO34-AO33) -> 0
B36: ราคาต้นทุน Tester | K36: =SUM(AQ20:AQ28) -> 0 | AI36: รวมกำไรสุทธิ | AO36: =+AO35-AN28 -> 0
B38: เรทราคา
AI40: นฤมล | AO40: จนท. R&D
O41: Probiotic ตัวหนังสือสีเขียว | AI41: =AJ8 -> 0
O42: เพิ่ม/ลด/ปรับเปลี่ยน สารสกัด โดส ผู้จัดจำหน่าย ประเทศ ตัวหนังสือสีแดง
B46: หมายเหตุ
AD47: 2.75

Sheet Tester
B2: ชื่อแบบฟอร์ม : สูตร | V2: เลขที่แบบฟอร์ม : F-OP-RD-002 | AK2: แก้ไขครั้งที่ : 0 | AW2: หน้านี้จะลิงค์กับหน้าต้นทุน จะไม่บอกราคาให้ผู้ช่วยทราบ
B3: เตรียมโดย : - | V3: อนุมัติโดย : -
B5: สูตรTester
B6: นามผู้ซื้อ | I6: บริษัท โนเวล ฟอร์มูลา กรุป จำกัด | Z6: เลขที่สูตร | AJ6: F 670814-609#2
B8: ประเภทของผลิตภัณฑ์ | I8: อาหารเสริมบำรุงผิว | Z8: วันที่ | AJ8: 45566
B10: ชื่อผลิตภัณฑ์ / เลข อย. | Z10: พนักงานขาย | AJ10: วรัญญา ปราบณรงค์
B12: จำนวนที่สั่งผลิต | I12: =1500000+(1500000*5)/100 -> 1575000 | P12: หน่วย | T12: แคปซูล
B14: ลำดับ | D14: สารสกัด | P14: ปริมาณ | V14: ปริมาณที่ใช้ | Z14: ร้อยละ | AA14: ราคา / ก.ก. | AE14: ราคา / มก. | AI14: ผู้จัดจำหน่าย | AM14: รหัส | AN14: ราคา/แพ็ค | AO14: ปริมาณ | AP14: ปริมาณ g. | AQ14: ราคา / mg.
B15: No. | P15: (มล.) | V15: ผลิต (ก.ก.) | Z15: (%) (Mg.) | AA15: Price / Kg. | AE15: Price / Mg. | AI15: Supplier | AM15: วัตถุดิบ | AO15: mg.
B16: 1 | D16: ='คิดต้นทุน สรุป'!D16:O16 -> 0 | P16: ='คิดต้นทุน สรุป'!P16:U16 -> 0 | V16: =SUM(P16*I12/1000000) -> 0 | Z16: =P16*100/P28 -> #DIV/0! | AE16: =SUM(AA16/1000000*P16) -> 0 | AI16: ='คิดต้นทุน สรุป'!AI16:AL16 -> 0 | AM16: ='คิดต้นทุน สรุป'!AM16 -> 0 | AO16: =+P16*$AP$29 -> 0 | AP16: =+AO16/1000 -> 0 | AQ16: =SUM(AA16/1000000*AO16) -> 0
B17: 2 | D17: ='คิดต้นทุน สรุป'!D17:O17 -> 0 | P17: ='คิดต้นทุน สรุป'!P17:U17 -> 0 | V17: =SUM(P17*I12/1000000) -> 0 | Z17: =P17*100/P28 -> #DIV/0! | AE17: =SUM(AA17/1000000*P17) -> 0 | AI17: ='คิดต้นทุน สรุป'!AI17:AL17 -> 0 | AM17: ='คิดต้นทุน สรุป'!AM17 -> 0 | AO17: =+P17*$AP$29 -> 0 | AP17: =+AO17/1000 -> 0 | AQ17: =SUM(AA17/1000000*AO17) -> 0
B18: 4 | D18: ='คิดต้นทุน สรุป'!D18:O18 -> 0 | P18: ='คิดต้นทุน สรุป'!P18:U18 -> 0 | V18: =SUM(P18*I12/1000000) -> 0 | Z18: =P18*100/P28 -> #DIV/0! | AE18: =SUM(AA18/1000000*P18) -> 0 | AI18: ='คิดต้นทุน สรุป'!AI18:AL18 -> 0 | AM18: ='คิดต้นทุน สรุป'!AM18 -> 0 | AO18: =+P18*$AP$29 -> 0 | AP18: =+AO18/1000 -> 0 | AQ18: =SUM(AA18/1000000*AO18) -> 0
B19: 5 | D19: ='คิดต้นทุน สรุป'!D19:O19 -> 0 | P19: ='คิดต้นทุน สรุป'!P19:U19 -> 0 | V19: =SUM(P19*I12/1000000) -> 0 | Z19: =P19*100/P28 -> #DIV/0! | AE19: =SUM(AA19/1000000*P19) -> 0 | AI19: ='คิดต้นทุน สรุป'!AI19:AL19 -> 0 | AM19: ='คิดต้นทุน สรุป'!AM19 -> 0 | AO19: =+P19*$AP$29 -> 0 | AP19: =+AO19/1000 -> 0 | AQ19: =SUM(AA19/1000000*AO19) -> 0
B20: 6 | D20: ='คิดต้นทุน สรุป'!D21:O21 -> 0 | P20: ='คิดต้นทุน สรุป'!P21:U21 -> 0 | V20: =SUM(P20*I12/1000000) -> 0 | Z20: =P20*100/P28 -> #DIV/0! | AE20: =SUM(AA20/1000000*P20) -> 0 | AI20: ='คิดต้นทุน สรุป'!AI21:AL21 -> 0 | AM20: ='คิดต้นทุน สรุป'!AM21 -> 0 | AO20: =+P20*$AP$29 -> 0 | AP20: =+AO20/1000 -> 0 | AQ20: =SUM(AA20/1000000*AO20) -> 0
B21: 7 | D21: ='คิดต้นทุน สรุป'!D22:O22 -> 0 | P21: ='คิดต้นทุน สรุป'!P22:U22 -> 0 | V21: =SUM(P21*I12/1000000) -> 0 | Z21: =P21*100/P28 -> #DIV/0! | AE21: =SUM(AA21/1000000*P21) -> 0 | AI21: ='คิดต้นทุน สรุป'!AI22:AL22 -> 0 | AM21: ='คิดต้นทุน สรุป'!AM22 -> 0 | AO21: =+P21*$AP$29 -> 0 | AP21: =+AO21/1000 -> 0 | AQ21: =SUM(AA21/1000000*AO21) -> 0
B22: 8 | D22: ='คิดต้นทุน สรุป'!D23:O23 -> 0 | P22: ='คิดต้นทุน สรุป'!P23:U23 -> 0 | V22: =SUM(P22*I12/1000000) -> 0 | Z22: =P22*100/P28 -> #DIV/0! | AE22: =SUM(AA22/1000000*P22) -> 0 | AI22: ='คิดต้นทุน สรุป'!AI23:AL23 -> 0 | AM22: ='คิดต้นทุน สรุป'!AM23 -> 0 | AO22: =+P22*$AP$29 -> 0 | AP22: =+AO22/1000 -> 0 | AQ22: =SUM(AA22/1000000*AO22) -> 0
B23: 9 | D23: ='คิดต้นทุน สรุป'!D20:O20 -> 0 | P23: ='คิดต้นทุน สรุป'!P20:U20 -> 0 | V23: =SUM(P23*I12/1000000) -> 0 | Z23: =P23*100/P28 -> #DIV/0! | AE23: =SUM(AA23/1000000*P23) -> 0 | AI23: ='คิดต้นทุน สรุป'!AI20:AL20 -> 0 | AM23: ='คิดต้นทุน สรุป'!AM20 -> 0 | AO23: =+P23*$AP$29 -> 0 | AP23: =+AO23/1000 -> 0 | AQ23: =SUM(AA23/1000000*AO23) -> 0
B24: 10 | D24: ='คิดต้นทุน สรุป'!D24:O24 -> 0 | P24: ='คิดต้นทุน สรุป'!P24:U24 -> 0 | V24: =SUM(P24*I12/1000000) -> 0 | Z24: =P24*100/P28 -> #DIV/0! | AE24: =SUM(AA24/1000000*P24) -> 0 | AI24: ='คิดต้นทุน สรุป'!AI24:AL24 -> 0 | AM24: ='คิดต้นทุน สรุป'!AM24 -> 0 | AO24: =+P24*$AP$29 -> 0 | AP24: =+AO24/1000 -> 0 | AQ24: =SUM(AA24/1000000*AO24) -> 0
B25: 11 | D25: ='คิดต้นทุน สรุป'!D25:O25 -> 0 | P25: ='คิดต้นทุน สรุป'!P25:U25 -> 0 | V25: =SUM(P25*I12/1000000) -> 0 | Z25: =P25*100/P28 -> #DIV/0! | AE25: =SUM(AA25/1000000*P25) -> 0 | AI25: ='คิดต้นทุน สรุป'!AI25:AL25 -> 0 | AM25: ='คิดต้นทุน สรุป'!AM25 -> 0 | AO25: =+P25*$AP$29 -> 0 | AP25: =+AO25/1000 -> 0 | AQ25: =SUM(AA25/1000000*AO25) -> 0
B26: 12 | D26: ='คิดต้นทุน สรุป'!D26:O26 -> 0 | P26: ='คิดต้นทุน สรุป'!P26:U26 -> 0 | V26: =SUM(P26*I12/1000000) -> 0 | Z26: =P26*100/P28 -> #DIV/0! | AE26: =SUM(AA26/1000000*P26) -> 0 | AI26: ='คิดต้นทุน สรุป'!AI26:AL26 -> 0 | AM26: ='คิดต้นทุน สรุป'!AM26 -> 0 | AO26: =+P26*$AP$29 -> 0 | AP26: =+AO26/1000 -> 0 | AQ26: =SUM(AA26/1000000*AO26) -> 0
B27: 13 | D27: ='คิดต้นทุน สรุป'!D27:O27 -> 0 | P27: ='คิดต้นทุน สรุป'!P27:U27 -> 0 | V27: =SUM(P27*I12/1000000) -> 0 | Z27: =P27*100/P28 -> #DIV/0! | AE27: =SUM(AA27/1000000*P27) -> 0 | AI27: ='คิดต้นทุน สรุป'!AI27:AL27 -> 0 | AM27: ='คิดต้นทุน สรุป'!AM27 -> 0 | AO27: =+P27*$AP$29 -> 0 | AP27: =+AO27/1000 -> 0 | AQ27: =SUM(AA27/1000000*AO27) -> 0
B28: ปริมาณส่วนผสม / หน่วย / กก. | P28: =SUM(P16:U27) -> 0 | V28: =SUM(V16:Y27) -> 0 | Z28: =SUM(Z16:Z27) -> #DIV/0! | AE28: ต้นทุนราคา/แพ็ค | AM28: ='คิดต้นทุน สรุป'!AM25 -> 0 | AN28: =SUM(AN21:AN27) -> 0 | AO28: =+AE29*AP29 -> 96
B29: แคปซูล #00 | AA29: ราคา | AE29: 0.6 | AN29: จำนวน Tester | AP29: 160 | AQ29: =+T12 -> แคปซูล
K34: ผู้ช่วยจนท. R&D | AI34: นฤมล | AO34: จนท. R&D
C35: ( / / ) | AI35: =AJ8 -> 45566
B38: ขั้นตอนการผสมสารและใช้ตะแกรง
B39: 1
B41: 2
B43: 3
B45: 4
B46: 5
B47: 6
B49: ปริมาณน้ำที่ใช้ | O49: ขนาด/สี แคปซูล | AD49: รูปทรงเม็ดตอก | AO49: ขนาดซองบรรจุ
O50: #00 สีขาว | AD50: -

Sheet ส่งตรวจ
B2: ชื่อแบบฟอร์ม : สูตร | V2: เลขที่แบบฟอร์ม : F-OP-RD-002 | AK2: แก้ไขครั้งที่ : 0
B3: เตรียมโดย : - | V3: อนุมัติโดย : -
B5: สูตรผลิตจริง | AW5: จะลิงค์กับสูตรขึ้นทะเบียน
B6: นามผู้ซื้อ | Z6: เลขที่สูตร
B8: ประเภทของผลิตภัณฑ์ | Z8: วันที่
B10: ชื่อผลิตภัณฑ์ / เลข อย. | Z10: พนักงานขาย
B12: จำนวนที่สั่งผลิต | P12: หน่วย | T12: แคปซูล
B14: ลำดับ | D14: สารสกัด | P14: ปริมาณ | V14: ปริมาณที่ใช้ | Z14: ร้อยละ | AA14: ราคา / ก.ก. | AE14: ราคา / มก. | AI14: ผู้จัดจำหน่าย | AM14: รหัส | AN14: ราคา/แพ็ค | AO14: ปริมาณ | AP14: ปริมาณ g. | AQ14: ราคา / mg.
B15: No. | P15: (มล.) | V15: ผลิต (ก.ก.) | Z15: (%) (Mg.) | AA15: Price / Kg. | AE15: Price / Mg. | AI15: Supplier | AM15: วัตถุดิบ | AO15: mg.
B16: 1 | V16: =SUM(P16*I12/1000000) -> 0 | Z16: =P16*100/P36 -> #DIV/0! | AE16: =SUM(AA16/1000000*P16) -> 0 | AO16: =+P16*AP39 -> 0 | AP16: =+AO16/1000 -> 0 | AQ16: =SUM(AA16/1000000*AO16) -> 0
B17: 2 | V17: =SUM(P17*I12/1000000) -> 0 | Z17: =P17*100/P36 -> #DIV/0! | AE17: =SUM(AA17/1000000*P17) -> 0 | AO17: =+P17*AP39 -> 0 | AP17: =+AO17/1000 -> 0 | AQ17: =SUM(AA17/1000000*AO17) -> 0
B18: 3 | V18: =SUM(P18*I12/1000000) -> 0 | Z18: =P18*100/P36 -> #DIV/0! | AE18: =SUM(AA18/1000000*P18) -> 0 | AO18: =+P18*AP39 -> 0 | AP18: =+AO18/1000 -> 0 | AQ18: =SUM(AA18/1000000*AO18) -> 0
B19: 4 | V19: =SUM(P19*I12/1000000) -> 0 | Z19: =P19*100/P36 -> #DIV/0! | AE19: =SUM(AA19/1000000*P19) -> 0 | AO19: =+P19*AP39 -> 0 | AP19: =+AO19/1000 -> 0 | AQ19: =SUM(AA19/1000000*AO19) -> 0
B20: 5 | V20: =SUM(P20*I12/1000000) -> 0 | Z20: =P20*100/P36 -> #DIV/0! | AE20: =SUM(AA20/1000000*P20) -> 0 | AO20: =+P20*AP39 -> 0 | AP20: =+AO20/1000 -> 0 | AQ20: =SUM(AA20/1000000*AO20) -> 0
B21: 6 | V21: =SUM(P21*I12/1000000) -> 0 | Z21: =P21*100/P36 -> #DIV/0! | AE21: =SUM(AA21/1000000*P21) -> 0 | AO21: =+P21*AP39 -> 0 | AP21: =+AO21/1000 -> 0 | AQ21: =SUM(AA21/1000000*AO21) -> 0
B22: 7 | V22: =SUM(P22*I12/1000000) -> 0 | Z22: =P22*100/P36 -> #DIV/0! | AE22: =SUM(AA22/1000000*P22) -> 0 | AO22: =+P22*AP39 -> 0 | AP22: =+AO22/1000 -> 0 | AQ22: =SUM(AA22/1000000*AO22) -> 0
B23: 8 | V23: =SUM(P23*I12/1000000) -> 0 | Z23: =P23*100/P36 -> #DIV/0! | AE23: =SUM(AA23/1000000*P23) -> 0 | AO23: =+P23*AP39 -> 0 | AP23: =+AO23/1000 -> 0 | AQ23: =SUM(AA23/1000000*AO23) -> 0
B24: 9 | V24: =SUM(P24*I12/1000000) -> 0 | Z24: =P24*100/P36 -> #DIV/0! | AE24: =SUM(AA24/1000000*P24) -> 0 | AO24: =+P24*AP39 -> 0 | AP24: =+AO24/1000 -> 0 | AQ24: =SUM(AA24/1000000*AO24) -> 0
B25: 10 | V25: =SUM(P25*I12/1000000) -> 0 | Z25: =P25*100/P36 -> #DIV/0! | AE25: =SUM(AA25/1000000*P25) -> 0 | AO25: =+P25*AP39 -> 0 | AP25: =+AO25/1000 -> 0 | AQ25: =SUM(AA25/1000000*AO25) -> 0
B26: 11 | V26: =SUM(P26*I12/1000000) -> 0 | Z26: =P26*100/P36 -> #DIV/0! | AE26: =SUM(AA26/1000000*P26) -> 0 | AO26: =+P26*AP39 -> 0 | AP26: =+AO26/1000 -> 0 | AQ26: =SUM(AA26/1000000*AO26) -> 0
B27: 12 | V27: =SUM(P27*I12/1000000) -> 0 | Z27: =P27*100/P36 -> #DIV/0! | AE27: =SUM(AA27/1000000*P27) -> 0 | AO27: =+P27*AP39 -> 0 | AP27: =+AO27/1000 -> 0 | AQ27: =SUM(AA27/1000000*AO27) -> 0
B28: 13 | V28: =SUM(P28*I12/1000000) -> 0 | Z28: =P28*100/P36 -> #DIV/0! | AE28: =SUM(AA28/1000000*P28) -> 0 | AO28: =+P28*AP39 -> 0 | AP28: =+AO28/1000 -> 0 | AQ28: =SUM(AA28/1000000*AO28) -> 0
B29: 14 | V29: =SUM(P29*I12/1000000) -> 0 | Z29: =P29*100/P36 -> #DIV/0! | AE29: =SUM(AA29/1000000*P29) -> 0 | AO29: =+P29*AP39 -> 0 | AP29: =+AO29/1000 -> 0 | AQ29: =SUM(AA29/1000000*AO29) -> 0
B30: 15 | V30: =SUM(P30*I12/1000000) -> 0 | Z30: =P30*100/P36 -> #DIV/0! | AE30: =SUM(AA30/1000000*P30) -> 0 | AO30: =+P30*AP39 -> 0 | AP30: =+AO30/1000 -> 0 | AQ30: =SUM(AA30/1000000*AO30) -> 0
B31: 16 | V31: =SUM(P31*I12/1000000) -> 0 | Z31: =P31*100/P36 -> #DIV/0! | AE31: =SUM(AA31/1000000*P31) -> 0 | AO31: =+P31*AP39 -> 0 | AP31: =+AO31/1000 -> 0 | AQ31: =SUM(AA31/1000000*AO31) -> 0
B32: 17 | V32: =SUM(P32*I12/1000000) -> 0 | Z32: =P32*100/P36 -> #DIV/0! | AE32: =SUM(AA32/1000000*P32) -> 0 | AO32: =+P32*AP39 -> 0 | AP32: =+AO32/1000 -> 0 | AQ32: =SUM(AA32/1000000*AO32) -> 0
B33: 18 | V33: =SUM(P33*I12/1000000) -> 0 | Z33: =P33*100/P36 -> #DIV/0! | AE33: =SUM(AA33/1000000*P33) -> 0 | AO33: =+P33*AP39 -> 0 | AP33: =+AO33/1000 -> 0 | AQ33: =SUM(AA33/1000000*AO33) -> 0
B34: 19 | V34: =SUM(P34*I12/1000000) -> 0 | Z34: =P34*100/P36 -> #DIV/0! | AE34: =SUM(AA34/1000000*P34) -> 0 | AO34: =+P34*AP39 -> 0 | AP34: =+AO34/1000 -> 0 | AQ34: =SUM(AA34/1000000*AO34) -> 0
B35: 20 | V35: =SUM(P35*I12/1000000) -> 0 | Z35: =P35*100/P36 -> #DIV/0! | AE35: =SUM(AA35/1000000*P35) -> 0 | AO35: =+P35*AP39 -> 0 | AP35: =+AO35/1000 -> 0 | AQ35: =SUM(AA35/1000000*AO35) -> 0
B36: ปริมาณส่วนผสม / หน่วย / กก. | P36: =SUM(P16:U35) -> 0 | V36: =SUM(V16:Y35) -> 0 | Z36: =SUM(Z16:Z35) -> #DIV/0! | AE36: ต้นทุนราคา/แพ็ค | AN36: =SUM(AN18:AN35) -> 0 | AO36: =+AE39*AP39 -> 16
B37: งานแคปซูล ( แคปซูลสี ค่าแคปซูล #00 ราคา 0.6 บาท, ค่าแคปซูล #0 ราคา 0.5 บาท ) ( แคปซูลขาว ค่าแคปซูล #00 ราคา 0.2 บาท, ค่าแคปซูล #0 ราคา 0.1 บาท )
B38: ( งานชงดื่ม,กรอกปาก Aluminium Foil ราคา 1.5 บาท ) ( ตอกเม็ด+เคลือบ 0.8 บาท )
B39: แคปซูล #00 | AA39: ราคา | AE39: 0.1 | AN39: จำนวน Tester | AP39: 160 | AQ39: =+T12 -> แคปซูล
B41: ราคาต้นทุนส่วนผสม / หน่วย | K41: =SUM(AE16:AH39) -> 0.1 | AI41: รวมราคาต้นทุนส่วนผสม | AO41: =SUM(I12*K41) -> 0
B42: ราคาขาย / หน่วย | AI42: รวมราคาขาย | AO42: =SUM(I12*K42) -> 0
B43: กำไร / หน่วย | K43: =SUM(K42-K41) -> -0.1 | Z43: =K43*100/K42 -> #DIV/0! | AI43: รวมกำไร | AO43: =SUM(AO42-AO41) -> 0
B44: ราคาต้นทุน Tester | K44: =SUM(AQ18:AQ36) -> 0 | AI44: รวมกำไรสุทธิ | AO44: =+AO43-AN36 -> 0
B46: เรทราคา
AI48: นฤมล | AO48: จนท. R&D
O49: Probiotic ตัวหนังสือสีเขียว | AI49: =AJ8 -> 0
...
